2018-06-29 11:14:13,438 [django.request:93] [base:get_response] [WARNING]- Not Found: /
2018-06-29 11:14:32,678 [HttpRunnerManager:45] [views:login] [INFO]- yinquanwang 登录成功
2018-06-29 11:14:33,058 [django.request:93] [base:get_response] [WARNING]- Not Found: /static/assets/js/commons.js
2018-06-29 11:14:33,499 [django.request:93] [base:get_response] [WARNING]- Not Found: /static/assets/js/commons.js
2018-06-29 11:14:58,797 [HttpRunnerManager:45] [views:login] [INFO]- yinquanwang 登录成功
2018-06-29 11:48:11,403 [HttpRunnerManager:151] [operation:add_case_data] [INFO]- 的用例添加成功: {'test': {'request': {'method': 'POST', 'url': ''}, 'name': '的'}}
2018-06-29 11:48:48,076 [HttpRunnerManager:45] [views:login] [INFO]- yinquanwang 登录成功
2018-07-02 13:34:18,047 [django.request:93] [base:get_response] [WARNING]- Not Found: /static/assets/css/css-index.css
2018-07-02 13:34:18,057 [django.request:93] [base:get_response] [WARNING]- Not Found: /static/assets/img/logo.png
2018-07-02 13:34:18,268 [django.request:93] [base:get_response] [WARNING]- Not Found: /static/assets/js/custom.js
2018-07-02 13:34:18,270 [django.request:93] [base:get_response] [WARNING]- Not Found: /static/assets/js/jquery.sticky.js
2018-07-02 13:34:18,276 [django.request:93] [base:get_response] [WARNING]- Not Found: /static/assets/js/wow.min.js
2018-07-02 13:34:18,278 [django.request:93] [base:get_response] [WARNING]- Not Found: /static/assets/js/owl.carousel.min.js
2018-07-02 13:34:18,296 [django.request:93] [base:get_response] [WARNING]- Not Found: /static/assets/img/bg.jpg
2018-07-02 13:34:18,299 [django.request:93] [base:get_response] [WARNING]- Not Found: /static/assets/img/loading.GIF
2018-07-02 13:34:18,352 [django.request:93] [base:get_response] [WARNING]- Not Found: /static/assets/js/custom.js
2018-07-02 13:34:18,364 [django.request:93] [base:get_response] [WARNING]- Not Found: /static/assets/js/jquery.sticky.js
2018-07-02 13:34:18,370 [django.request:93] [base:get_response] [WARNING]- Not Found: /static/assets/js/wow.min.js
2018-07-02 13:34:18,383 [django.request:93] [base:get_response] [WARNING]- Not Found: /static/assets/js/owl.carousel.min.js
2018-07-02 13:34:18,578 [django.request:93] [base:get_response] [WARNING]- Not Found: /static/assets/img/favicon.ico
2018-07-02 13:34:21,442 [django.request:93] [base:get_response] [WARNING]- Not Found: /static/assets/css/css-index.css
2018-07-02 13:34:21,445 [django.request:93] [base:get_response] [WARNING]- Not Found: /static/assets/js/custom.js
2018-07-02 13:34:21,449 [django.request:93] [base:get_response] [WARNING]- Not Found: /static/assets/img/logo.png
2018-07-02 13:34:21,484 [django.request:93] [base:get_response] [WARNING]- Not Found: /static/assets/js/jquery.sticky.js
2018-07-02 13:34:21,487 [django.request:93] [base:get_response] [WARNING]- Not Found: /static/assets/js/wow.min.js
2018-07-02 13:34:21,492 [django.request:93] [base:get_response] [WARNING]- Not Found: /static/assets/js/owl.carousel.min.js
2018-07-02 13:34:21,508 [django.request:93] [base:get_response] [WARNING]- Not Found: /static/assets/js/custom.js
2018-07-02 13:34:21,516 [django.request:93] [base:get_response] [WARNING]- Not Found: /static/assets/img/bg.jpg
2018-07-02 13:34:21,519 [django.request:93] [base:get_response] [WARNING]- Not Found: /static/assets/img/loading.GIF
2018-07-02 13:34:21,531 [django.request:93] [base:get_response] [WARNING]- Not Found: /static/assets/js/jquery.sticky.js
2018-07-02 13:34:21,540 [django.request:93] [base:get_response] [WARNING]- Not Found: /static/assets/js/wow.min.js
2018-07-02 13:34:21,545 [django.request:93] [base:get_response] [WARNING]- Not Found: /static/assets/js/owl.carousel.min.js
2018-07-02 13:34:22,424 [django.request:93] [base:get_response] [WARNING]- Not Found: /static/assets/css/css-index.css
2018-07-02 13:34:22,426 [django.request:93] [base:get_response] [WARNING]- Not Found: /static/assets/img/logo.png
2018-07-02 13:34:22,429 [django.request:93] [base:get_response] [WARNING]- Not Found: /static/assets/js/custom.js
2018-07-02 13:34:22,465 [django.request:93] [base:get_response] [WARNING]- Not Found: /static/assets/js/jquery.sticky.js
2018-07-02 13:34:22,466 [django.request:93] [base:get_response] [WARNING]- Not Found: /static/assets/js/wow.min.js
2018-07-02 13:34:22,468 [django.request:93] [base:get_response] [WARNING]- Not Found: /static/assets/js/owl.carousel.min.js
2018-07-02 13:34:22,480 [django.request:93] [base:get_response] [WARNING]- Not Found: /static/assets/js/custom.js
2018-07-02 13:34:22,483 [django.request:93] [base:get_response] [WARNING]- Not Found: /static/assets/img/bg.jpg
2018-07-02 13:34:22,490 [django.request:93] [base:get_response] [WARNING]- Not Found: /static/assets/img/loading.GIF
2018-07-02 13:34:22,498 [django.request:93] [base:get_response] [WARNING]- Not Found: /static/assets/js/jquery.sticky.js
2018-07-02 13:34:22,506 [django.request:93] [base:get_response] [WARNING]- Not Found: /static/assets/js/wow.min.js
2018-07-02 13:34:22,509 [django.request:93] [base:get_response] [WARNING]- Not Found: /static/assets/js/owl.carousel.min.js
2018-07-02 13:35:30,488 [HttpRunnerManager:45] [views:login] [INFO]- yinquanwang 登录成功
2018-07-02 13:48:28,352 [HttpRunnerManager:45] [views:login] [INFO]- yinquanwang 登录成功
2018-07-02 13:53:41,984 [django.request:118] [exception:handle_uncaught_exception] [ERROR]- Internal Server Error: /api/test_list/1/
Traceback (most recent call last):
  File "E:\Python35\lib\site-packages\django\core\handlers\exception.py", line 35, in inner
    response = get_response(request)
  File "E:\Python35\lib\site-packages\django\core\handlers\base.py", line 128, in _get_response
    response = self.process_exception_by_middleware(e, request)
  File "E:\Python35\lib\site-packages\django\core\handlers\base.py", line 126, in _get_response
    response = wrapped_callback(request, *callback_args, **callback_kwargs)
  File "D:/HttpRunnerManager\HttpRunnerManager\activator.py", line 15, in process
    result = fun(request, index) if index else fun(request)
  File "D:/HttpRunnerManager\ApiManager\views.py", line 379, in test_list
    filter_query = set_filter_session(request)
  File "D:/HttpRunnerManager\ApiManager\utils\common.py", line 439, in set_filter_session
    'belong_project': request.session['project'],
  File "E:\Python35\lib\site-packages\django\contrib\sessions\backends\base.py", line 55, in __getitem__
    return self._session[key]
KeyError: 'project'
2018-07-02 13:53:49,147 [django.request:118] [exception:handle_uncaught_exception] [ERROR]- Internal Server Error: /api/test_list/1/
Traceback (most recent call last):
  File "E:\Python35\lib\site-packages\django\core\handlers\exception.py", line 35, in inner
    response = get_response(request)
  File "E:\Python35\lib\site-packages\django\core\handlers\base.py", line 128, in _get_response
    response = self.process_exception_by_middleware(e, request)
  File "E:\Python35\lib\site-packages\django\core\handlers\base.py", line 126, in _get_response
    response = wrapped_callback(request, *callback_args, **callback_kwargs)
  File "D:/HttpRunnerManager\HttpRunnerManager\activator.py", line 15, in process
    result = fun(request, index) if index else fun(request)
  File "D:/HttpRunnerManager\ApiManager\views.py", line 379, in test_list
    filter_query = set_filter_session(request)
  File "D:/HttpRunnerManager\ApiManager\utils\common.py", line 439, in set_filter_session
    'belong_project': request.session['project'],
  File "E:\Python35\lib\site-packages\django\contrib\sessions\backends\base.py", line 55, in __getitem__
    return self._session[key]
KeyError: 'project'
2018-07-02 13:54:04,117 [HttpRunnerManager:78] [views:log_out] [INFO]- yinquanwang退出
2018-07-02 13:54:07,459 [HttpRunnerManager:45] [views:login] [INFO]- yinquanwang 登录成功
2018-07-02 13:57:09,661 [HttpRunnerManager:78] [views:log_out] [INFO]- yinquanwang退出
2018-07-02 13:57:11,824 [HttpRunnerManager:45] [views:login] [INFO]- yinquanwang 登录成功
2018-07-02 14:04:39,039 [HttpRunnerManager:78] [views:log_out] [INFO]- yinquanwang退出
2018-07-02 14:04:44,830 [HttpRunnerManager:45] [views:login] [INFO]- yinquanwang 登录成功
2018-07-02 14:04:54,650 [django.request:118] [exception:handle_uncaught_exception] [ERROR]- Internal Server Error: /api/test_list/1/
Traceback (most recent call last):
  File "E:\Python35\lib\site-packages\django\core\handlers\exception.py", line 35, in inner
    response = get_response(request)
  File "E:\Python35\lib\site-packages\django\core\handlers\base.py", line 128, in _get_response
    response = self.process_exception_by_middleware(e, request)
  File "E:\Python35\lib\site-packages\django\core\handlers\base.py", line 126, in _get_response
    response = wrapped_callback(request, *callback_args, **callback_kwargs)
  File "D:\HttpRunnerManager\HttpRunnerManager\activator.py", line 15, in process
    result = fun(request, index) if index else fun(request)
  File "D:\HttpRunnerManager\ApiManager\views.py", line 379, in test_list
    filter_query = set_filter_session(request)
  File "D:\HttpRunnerManager\ApiManager\utils\common.py", line 432, in set_filter_session
    request.session['module'] = ModuleInfo.objects.get(id=request.POST.get('module')).module_name
  File "E:\Python35\lib\site-packages\django\db\models\manager.py", line 82, in manager_method
    return getattr(self.get_queryset(), name)(*args, **kwargs)
  File "E:\Python35\lib\site-packages\django\db\models\query.py", line 394, in get
    clone = self.filter(*args, **kwargs)
  File "E:\Python35\lib\site-packages\django\db\models\query.py", line 836, in filter
    return self._filter_or_exclude(False, *args, **kwargs)
  File "E:\Python35\lib\site-packages\django\db\models\query.py", line 854, in _filter_or_exclude
    clone.query.add_q(Q(*args, **kwargs))
  File "E:\Python35\lib\site-packages\django\db\models\sql\query.py", line 1253, in add_q
    clause, _ = self._add_q(q_object, self.used_aliases)
  File "E:\Python35\lib\site-packages\django\db\models\sql\query.py", line 1277, in _add_q
    split_subq=split_subq,
  File "E:\Python35\lib\site-packages\django\db\models\sql\query.py", line 1215, in build_filter
    condition = self.build_lookup(lookups, col, value)
  File "E:\Python35\lib\site-packages\django\db\models\sql\query.py", line 1085, in build_lookup
    lookup = lookup_class(lhs, rhs)
  File "E:\Python35\lib\site-packages\django\db\models\lookups.py", line 18, in __init__
    self.rhs = self.get_prep_lookup()
  File "E:\Python35\lib\site-packages\django\db\models\lookups.py", line 68, in get_prep_lookup
    return self.lhs.output_field.get_prep_value(self.rhs)
  File "E:\Python35\lib\site-packages\django\db\models\fields\__init__.py", line 947, in get_prep_value
    return int(value)
ValueError: invalid literal for int() with base 10: ''
2018-07-02 14:06:02,565 [django.request:118] [exception:handle_uncaught_exception] [ERROR]- Internal Server Error: /api/config_list/1/
Traceback (most recent call last):
  File "E:\Python35\lib\site-packages\django\core\handlers\exception.py", line 35, in inner
    response = get_response(request)
  File "E:\Python35\lib\site-packages\django\core\handlers\base.py", line 128, in _get_response
    response = self.process_exception_by_middleware(e, request)
  File "E:\Python35\lib\site-packages\django\core\handlers\base.py", line 126, in _get_response
    response = wrapped_callback(request, *callback_args, **callback_kwargs)
  File "D:\HttpRunnerManager\HttpRunnerManager\activator.py", line 15, in process
    result = fun(request, index) if index else fun(request)
  File "D:\HttpRunnerManager\ApiManager\views.py", line 413, in config_list
    filter_query = set_filter_session(request)
  File "D:\HttpRunnerManager\ApiManager\utils\common.py", line 432, in set_filter_session
    request.session['module'] = ModuleInfo.objects.get(id=request.POST.get('module')).module_name
  File "E:\Python35\lib\site-packages\django\db\models\manager.py", line 82, in manager_method
    return getattr(self.get_queryset(), name)(*args, **kwargs)
  File "E:\Python35\lib\site-packages\django\db\models\query.py", line 394, in get
    clone = self.filter(*args, **kwargs)
  File "E:\Python35\lib\site-packages\django\db\models\query.py", line 836, in filter
    return self._filter_or_exclude(False, *args, **kwargs)
  File "E:\Python35\lib\site-packages\django\db\models\query.py", line 854, in _filter_or_exclude
    clone.query.add_q(Q(*args, **kwargs))
  File "E:\Python35\lib\site-packages\django\db\models\sql\query.py", line 1253, in add_q
    clause, _ = self._add_q(q_object, self.used_aliases)
  File "E:\Python35\lib\site-packages\django\db\models\sql\query.py", line 1277, in _add_q
    split_subq=split_subq,
  File "E:\Python35\lib\site-packages\django\db\models\sql\query.py", line 1215, in build_filter
    condition = self.build_lookup(lookups, col, value)
  File "E:\Python35\lib\site-packages\django\db\models\sql\query.py", line 1085, in build_lookup
    lookup = lookup_class(lhs, rhs)
  File "E:\Python35\lib\site-packages\django\db\models\lookups.py", line 18, in __init__
    self.rhs = self.get_prep_lookup()
  File "E:\Python35\lib\site-packages\django\db\models\lookups.py", line 68, in get_prep_lookup
    return self.lhs.output_field.get_prep_value(self.rhs)
  File "E:\Python35\lib\site-packages\django\db\models\fields\__init__.py", line 947, in get_prep_value
    return int(value)
ValueError: invalid literal for int() with base 10: ''
2018-07-02 14:24:14,328 [HttpRunnerManager:78] [views:log_out] [INFO]- yinquanwang退出
2018-07-02 14:24:16,921 [HttpRunnerManager:45] [views:login] [INFO]- yinquanwang 登录成功
2018-07-02 14:27:17,963 [django.request:118] [exception:handle_uncaught_exception] [ERROR]- Internal Server Error: /api/project_list/1/
Traceback (most recent call last):
  File "E:\Python35\lib\site-packages\django\template\base.py", line 475, in parse
    compile_func = self.tags[command]
KeyError: 'endif'

During handling of the above exception, another exception occurred:

Traceback (most recent call last):
  File "E:\Python35\lib\site-packages\django\core\handlers\exception.py", line 35, in inner
    response = get_response(request)
  File "E:\Python35\lib\site-packages\django\core\handlers\base.py", line 128, in _get_response
    response = self.process_exception_by_middleware(e, request)
  File "E:\Python35\lib\site-packages\django\core\handlers\base.py", line 126, in _get_response
    response = wrapped_callback(request, *callback_args, **callback_kwargs)
  File "D:\HttpRunnerManager\HttpRunnerManager\activator.py", line 15, in process
    result = fun(request, index) if index else fun(request)
  File "D:\HttpRunnerManager\ApiManager\views.py", line 323, in project_list
    return render_to_response('project_list.html', manage_info)
  File "E:\Python35\lib\site-packages\django\shortcuts.py", line 27, in render_to_response
    content = loader.render_to_string(template_name, context, using=using)
  File "E:\Python35\lib\site-packages\django\template\loader.py", line 61, in render_to_string
    template = get_template(template_name, using=using)
  File "E:\Python35\lib\site-packages\django\template\loader.py", line 15, in get_template
    return engine.get_template(template_name)
  File "E:\Python35\lib\site-packages\django\template\backends\django.py", line 34, in get_template
    return Template(self.engine.get_template(template_name), self)
  File "E:\Python35\lib\site-packages\django\template\engine.py", line 144, in get_template
    template, origin = self.find_template(template_name)
  File "E:\Python35\lib\site-packages\django\template\engine.py", line 126, in find_template
    template = loader.get_template(name, skip=skip)
  File "E:\Python35\lib\site-packages\django\template\loaders\base.py", line 30, in get_template
    contents, origin, origin.template_name, self.engine,
  File "E:\Python35\lib\site-packages\django\template\base.py", line 160, in __init__
    self.nodelist = self.compile_nodelist()
  File "E:\Python35\lib\site-packages\django\template\base.py", line 198, in compile_nodelist
    return parser.parse()
  File "E:\Python35\lib\site-packages\django\template\base.py", line 483, in parse
    raise self.error(token, e)
  File "E:\Python35\lib\site-packages\django\template\base.py", line 481, in parse
    compiled_result = compile_func(self, token)
  File "E:\Python35\lib\site-packages\django\template\loader_tags.py", line 290, in do_extends
    nodelist = parser.parse()
  File "E:\Python35\lib\site-packages\django\template\base.py", line 483, in parse
    raise self.error(token, e)
  File "E:\Python35\lib\site-packages\django\template\base.py", line 481, in parse
    compiled_result = compile_func(self, token)
  File "E:\Python35\lib\site-packages\django\template\loader_tags.py", line 233, in do_block
    nodelist = parser.parse(('endblock',))
  File "E:\Python35\lib\site-packages\django\template\base.py", line 477, in parse
    self.invalid_block_tag(token, command, parse_until)
  File "E:\Python35\lib\site-packages\django\template\base.py", line 533, in invalid_block_tag
    get_text_list(["'%s'" % p for p in parse_until], 'or'),
django.template.exceptions.TemplateSyntaxError: Invalid block tag on line 176: 'endif', expected 'endblock'. Did you forget to register or load this tag?
2018-07-02 14:27:44,949 [django.request:118] [exception:handle_uncaught_exception] [ERROR]- Internal Server Error: /api/project_list/1/
Traceback (most recent call last):
  File "E:\Python35\lib\site-packages\django\template\base.py", line 475, in parse
    compile_func = self.tags[command]
KeyError: 'endif'

During handling of the above exception, another exception occurred:

Traceback (most recent call last):
  File "E:\Python35\lib\site-packages\django\core\handlers\exception.py", line 35, in inner
    response = get_response(request)
  File "E:\Python35\lib\site-packages\django\core\handlers\base.py", line 128, in _get_response
    response = self.process_exception_by_middleware(e, request)
  File "E:\Python35\lib\site-packages\django\core\handlers\base.py", line 126, in _get_response
    response = wrapped_callback(request, *callback_args, **callback_kwargs)
  File "D:\HttpRunnerManager\HttpRunnerManager\activator.py", line 15, in process
    result = fun(request, index) if index else fun(request)
  File "D:\HttpRunnerManager\ApiManager\views.py", line 323, in project_list
    return render_to_response('project_list.html', manage_info)
  File "E:\Python35\lib\site-packages\django\shortcuts.py", line 27, in render_to_response
    content = loader.render_to_string(template_name, context, using=using)
  File "E:\Python35\lib\site-packages\django\template\loader.py", line 61, in render_to_string
    template = get_template(template_name, using=using)
  File "E:\Python35\lib\site-packages\django\template\loader.py", line 15, in get_template
    return engine.get_template(template_name)
  File "E:\Python35\lib\site-packages\django\template\backends\django.py", line 34, in get_template
    return Template(self.engine.get_template(template_name), self)
  File "E:\Python35\lib\site-packages\django\template\engine.py", line 144, in get_template
    template, origin = self.find_template(template_name)
  File "E:\Python35\lib\site-packages\django\template\engine.py", line 126, in find_template
    template = loader.get_template(name, skip=skip)
  File "E:\Python35\lib\site-packages\django\template\loaders\base.py", line 30, in get_template
    contents, origin, origin.template_name, self.engine,
  File "E:\Python35\lib\site-packages\django\template\base.py", line 160, in __init__
    self.nodelist = self.compile_nodelist()
  File "E:\Python35\lib\site-packages\django\template\base.py", line 198, in compile_nodelist
    return parser.parse()
  File "E:\Python35\lib\site-packages\django\template\base.py", line 483, in parse
    raise self.error(token, e)
  File "E:\Python35\lib\site-packages\django\template\base.py", line 481, in parse
    compiled_result = compile_func(self, token)
  File "E:\Python35\lib\site-packages\django\template\loader_tags.py", line 290, in do_extends
    nodelist = parser.parse()
  File "E:\Python35\lib\site-packages\django\template\base.py", line 483, in parse
    raise self.error(token, e)
  File "E:\Python35\lib\site-packages\django\template\base.py", line 481, in parse
    compiled_result = compile_func(self, token)
  File "E:\Python35\lib\site-packages\django\template\loader_tags.py", line 233, in do_block
    nodelist = parser.parse(('endblock',))
  File "E:\Python35\lib\site-packages\django\template\base.py", line 477, in parse
    self.invalid_block_tag(token, command, parse_until)
  File "E:\Python35\lib\site-packages\django\template\base.py", line 533, in invalid_block_tag
    get_text_list(["'%s'" % p for p in parse_until], 'or'),
django.template.exceptions.TemplateSyntaxError: Invalid block tag on line 176: 'endif', expected 'endblock'. Did you forget to register or load this tag?
2018-07-02 14:27:47,983 [django.request:118] [exception:handle_uncaught_exception] [ERROR]- Internal Server Error: /api/project_list/1/
Traceback (most recent call last):
  File "E:\Python35\lib\site-packages\django\template\base.py", line 475, in parse
    compile_func = self.tags[command]
KeyError: 'endif'

During handling of the above exception, another exception occurred:

Traceback (most recent call last):
  File "E:\Python35\lib\site-packages\django\core\handlers\exception.py", line 35, in inner
    response = get_response(request)
  File "E:\Python35\lib\site-packages\django\core\handlers\base.py", line 128, in _get_response
    response = self.process_exception_by_middleware(e, request)
  File "E:\Python35\lib\site-packages\django\core\handlers\base.py", line 126, in _get_response
    response = wrapped_callback(request, *callback_args, **callback_kwargs)
  File "D:\HttpRunnerManager\HttpRunnerManager\activator.py", line 15, in process
    result = fun(request, index) if index else fun(request)
  File "D:\HttpRunnerManager\ApiManager\views.py", line 323, in project_list
    return render_to_response('project_list.html', manage_info)
  File "E:\Python35\lib\site-packages\django\shortcuts.py", line 27, in render_to_response
    content = loader.render_to_string(template_name, context, using=using)
  File "E:\Python35\lib\site-packages\django\template\loader.py", line 61, in render_to_string
    template = get_template(template_name, using=using)
  File "E:\Python35\lib\site-packages\django\template\loader.py", line 15, in get_template
    return engine.get_template(template_name)
  File "E:\Python35\lib\site-packages\django\template\backends\django.py", line 34, in get_template
    return Template(self.engine.get_template(template_name), self)
  File "E:\Python35\lib\site-packages\django\template\engine.py", line 144, in get_template
    template, origin = self.find_template(template_name)
  File "E:\Python35\lib\site-packages\django\template\engine.py", line 126, in find_template
    template = loader.get_template(name, skip=skip)
  File "E:\Python35\lib\site-packages\django\template\loaders\base.py", line 30, in get_template
    contents, origin, origin.template_name, self.engine,
  File "E:\Python35\lib\site-packages\django\template\base.py", line 160, in __init__
    self.nodelist = self.compile_nodelist()
  File "E:\Python35\lib\site-packages\django\template\base.py", line 198, in compile_nodelist
    return parser.parse()
  File "E:\Python35\lib\site-packages\django\template\base.py", line 483, in parse
    raise self.error(token, e)
  File "E:\Python35\lib\site-packages\django\template\base.py", line 481, in parse
    compiled_result = compile_func(self, token)
  File "E:\Python35\lib\site-packages\django\template\loader_tags.py", line 290, in do_extends
    nodelist = parser.parse()
  File "E:\Python35\lib\site-packages\django\template\base.py", line 483, in parse
    raise self.error(token, e)
  File "E:\Python35\lib\site-packages\django\template\base.py", line 481, in parse
    compiled_result = compile_func(self, token)
  File "E:\Python35\lib\site-packages\django\template\loader_tags.py", line 233, in do_block
    nodelist = parser.parse(('endblock',))
  File "E:\Python35\lib\site-packages\django\template\base.py", line 477, in parse
    self.invalid_block_tag(token, command, parse_until)
  File "E:\Python35\lib\site-packages\django\template\base.py", line 533, in invalid_block_tag
    get_text_list(["'%s'" % p for p in parse_until], 'or'),
django.template.exceptions.TemplateSyntaxError: Invalid block tag on line 176: 'endif', expected 'endblock'. Did you forget to register or load this tag?
2018-07-02 14:28:16,257 [HttpRunnerManager:78] [views:log_out] [INFO]- yinquanwang退出
2018-07-02 14:28:18,192 [HttpRunnerManager:45] [views:login] [INFO]- yinquanwang 登录成功
2018-07-02 14:37:16,138 [django.request:118] [exception:handle_uncaught_exception] [ERROR]- Internal Server Error: /api/project_list/1/
Traceback (most recent call last):
  File "E:\Python35\lib\site-packages\django\core\handlers\exception.py", line 35, in inner
    response = get_response(request)
  File "E:\Python35\lib\site-packages\django\core\handlers\base.py", line 128, in _get_response
    response = self.process_exception_by_middleware(e, request)
  File "E:\Python35\lib\site-packages\django\core\handlers\base.py", line 126, in _get_response
    response = wrapped_callback(request, *callback_args, **callback_kwargs)
  File "D:\HttpRunnerManager\HttpRunnerManager\activator.py", line 15, in process
    result = fun(request, index) if index else fun(request)
  File "D:\HttpRunnerManager\ApiManager\views.py", line 311, in project_list
    filter_query = set_filter_session(request)
  File "D:\HttpRunnerManager\ApiManager\utils\common.py", line 442, in set_filter_session
    'belong_project': request.session['project'],
  File "E:\Python35\lib\site-packages\django\contrib\sessions\backends\base.py", line 55, in __getitem__
    return self._session[key]
KeyError: 'project'
2018-07-02 14:37:20,563 [django.request:118] [exception:handle_uncaught_exception] [ERROR]- Internal Server Error: /api/project_list/1/
Traceback (most recent call last):
  File "E:\Python35\lib\site-packages\django\core\handlers\exception.py", line 35, in inner
    response = get_response(request)
  File "E:\Python35\lib\site-packages\django\core\handlers\base.py", line 128, in _get_response
    response = self.process_exception_by_middleware(e, request)
  File "E:\Python35\lib\site-packages\django\core\handlers\base.py", line 126, in _get_response
    response = wrapped_callback(request, *callback_args, **callback_kwargs)
  File "D:\HttpRunnerManager\HttpRunnerManager\activator.py", line 15, in process
    result = fun(request, index) if index else fun(request)
  File "D:\HttpRunnerManager\ApiManager\views.py", line 311, in project_list
    filter_query = set_filter_session(request)
  File "D:\HttpRunnerManager\ApiManager\utils\common.py", line 442, in set_filter_session
    'belong_project': request.session['project'],
  File "E:\Python35\lib\site-packages\django\contrib\sessions\backends\base.py", line 55, in __getitem__
    return self._session[key]
KeyError: 'project'
2018-07-02 14:37:24,899 [HttpRunnerManager:78] [views:log_out] [INFO]- yinquanwang退出
2018-07-02 14:37:26,773 [HttpRunnerManager:45] [views:login] [INFO]- yinquanwang 登录成功
2018-07-02 14:37:30,837 [django.request:118] [exception:handle_uncaught_exception] [ERROR]- Internal Server Error: /api/add_case/
Traceback (most recent call last):
  File "E:\Python35\lib\site-packages\django\core\handlers\exception.py", line 35, in inner
    response = get_response(request)
  File "E:\Python35\lib\site-packages\django\core\handlers\base.py", line 128, in _get_response
    response = self.process_exception_by_middleware(e, request)
  File "E:\Python35\lib\site-packages\django\core\handlers\base.py", line 126, in _get_response
    response = wrapped_callback(request, *callback_args, **callback_kwargs)
  File "D:\HttpRunnerManager\HttpRunnerManager\activator.py", line 15, in process
    result = fun(request, index) if index else fun(request)
  File "D:\HttpRunnerManager\ApiManager\views.py", line 170, in add_case
    msg = case_info_logic(**testcase_info)
  File "D:\HttpRunnerManager\ApiManager\utils\common.py", line 210, in case_info_logic
    test = kwargs.pop('test')
KeyError: 'test'
2018-07-02 14:37:33,775 [django.request:118] [exception:handle_uncaught_exception] [ERROR]- Internal Server Error: /api/add_case/
Traceback (most recent call last):
  File "E:\Python35\lib\site-packages\django\core\handlers\exception.py", line 35, in inner
    response = get_response(request)
  File "E:\Python35\lib\site-packages\django\core\handlers\base.py", line 128, in _get_response
    response = self.process_exception_by_middleware(e, request)
  File "E:\Python35\lib\site-packages\django\core\handlers\base.py", line 126, in _get_response
    response = wrapped_callback(request, *callback_args, **callback_kwargs)
  File "D:\HttpRunnerManager\HttpRunnerManager\activator.py", line 15, in process
    result = fun(request, index) if index else fun(request)
  File "D:\HttpRunnerManager\ApiManager\views.py", line 170, in add_case
    msg = case_info_logic(**testcase_info)
  File "D:\HttpRunnerManager\ApiManager\utils\common.py", line 210, in case_info_logic
    test = kwargs.pop('test')
KeyError: 'test'
2018-07-02 14:39:25,603 [HttpRunnerManager:78] [views:log_out] [INFO]- yinquanwang退出
2018-07-02 14:39:27,918 [HttpRunnerManager:45] [views:login] [INFO]- yinquanwang 登录成功
2018-07-02 14:43:42,829 [HttpRunnerManager:78] [views:log_out] [INFO]- yinquanwang退出
2018-07-02 14:43:44,932 [HttpRunnerManager:45] [views:login] [INFO]- yinquanwang 登录成功
2018-07-02 14:47:52,728 [HttpRunnerManager:78] [views:log_out] [INFO]- yinquanwang退出
2018-07-02 14:47:54,981 [HttpRunnerManager:45] [views:login] [INFO]- yinquanwang 登录成功
2018-07-02 14:55:50,890 [HttpRunnerManager:78] [views:log_out] [INFO]- yinquanwang退出
2018-07-02 14:55:53,036 [HttpRunnerManager:45] [views:login] [INFO]- yinquanwang 登录成功
2018-07-02 14:57:17,859 [django.request:118] [exception:handle_uncaught_exception] [ERROR]- Internal Server Error: /api/module_list/1/
Traceback (most recent call last):
  File "E:\Python35\lib\site-packages\django\core\handlers\exception.py", line 35, in inner
    response = get_response(request)
  File "E:\Python35\lib\site-packages\django\core\handlers\base.py", line 128, in _get_response
    response = self.process_exception_by_middleware(e, request)
  File "E:\Python35\lib\site-packages\django\core\handlers\base.py", line 126, in _get_response
    response = wrapped_callback(request, *callback_args, **callback_kwargs)
  File "D:\HttpRunnerManager\HttpRunnerManager\activator.py", line 15, in process
    result = fun(request, index) if index else fun(request)
  File "D:\HttpRunnerManager\ApiManager\views.py", line 345, in module_list
    filter_query = set_filter_session(request)
  File "D:\HttpRunnerManager\ApiManager\utils\common.py", line 433, in set_filter_session
    request.session['module'] = ModuleInfo.objects.get(id=request.POST.get('module')).module_name
  File "E:\Python35\lib\site-packages\django\db\models\manager.py", line 82, in manager_method
    return getattr(self.get_queryset(), name)(*args, **kwargs)
  File "E:\Python35\lib\site-packages\django\db\models\query.py", line 394, in get
    clone = self.filter(*args, **kwargs)
  File "E:\Python35\lib\site-packages\django\db\models\query.py", line 836, in filter
    return self._filter_or_exclude(False, *args, **kwargs)
  File "E:\Python35\lib\site-packages\django\db\models\query.py", line 854, in _filter_or_exclude
    clone.query.add_q(Q(*args, **kwargs))
  File "E:\Python35\lib\site-packages\django\db\models\sql\query.py", line 1253, in add_q
    clause, _ = self._add_q(q_object, self.used_aliases)
  File "E:\Python35\lib\site-packages\django\db\models\sql\query.py", line 1277, in _add_q
    split_subq=split_subq,
  File "E:\Python35\lib\site-packages\django\db\models\sql\query.py", line 1215, in build_filter
    condition = self.build_lookup(lookups, col, value)
  File "E:\Python35\lib\site-packages\django\db\models\sql\query.py", line 1085, in build_lookup
    lookup = lookup_class(lhs, rhs)
  File "E:\Python35\lib\site-packages\django\db\models\lookups.py", line 18, in __init__
    self.rhs = self.get_prep_lookup()
  File "E:\Python35\lib\site-packages\django\db\models\lookups.py", line 68, in get_prep_lookup
    return self.lhs.output_field.get_prep_value(self.rhs)
  File "E:\Python35\lib\site-packages\django\db\models\fields\__init__.py", line 947, in get_prep_value
    return int(value)
ValueError: invalid literal for int() with base 10: '用例_quant_login_out(登入登出)'
2018-07-02 14:59:50,449 [HttpRunnerManager:78] [views:log_out] [INFO]- yinquanwang退出
2018-07-02 14:59:52,333 [HttpRunnerManager:45] [views:login] [INFO]- yinquanwang 登录成功
2018-07-23 08:59:26,673 [django.request:93] [base:get_response] [WARNING]- Not Found: /
2018-07-23 08:59:41,498 [django.request:118] [exception:handle_uncaught_exception] [ERROR]- Internal Server Error: /api/login/
Traceback (most recent call last):
  File "D:\python\lib\site-packages\django\db\backends\utils.py", line 85, in _execute
    return self.cursor.execute(sql, params)
  File "D:\python\lib\site-packages\django\db\backends\mysql\base.py", line 71, in execute
    return self.cursor.execute(query, args)
  File "D:\python\lib\site-packages\MySQLdb\cursors.py", line 250, in execute
    self.errorhandler(self, exc, value)
  File "D:\python\lib\site-packages\MySQLdb\connections.py", line 50, in defaulterrorhandler
    raise errorvalue
  File "D:\python\lib\site-packages\MySQLdb\cursors.py", line 247, in execute
    res = self._query(query)
  File "D:\python\lib\site-packages\MySQLdb\cursors.py", line 411, in _query
    rowcount = self._do_query(q)
  File "D:\python\lib\site-packages\MySQLdb\cursors.py", line 374, in _do_query
    db.query(q)
  File "D:\python\lib\site-packages\MySQLdb\connections.py", line 277, in query
    _mysql.connection.query(self, query)
_mysql_exceptions.ProgrammingError: (1146, "Table 'httprunner.userinfo' doesn't exist")

The above exception was the direct cause of the following exception:

Traceback (most recent call last):
  File "D:\python\lib\site-packages\django\core\handlers\exception.py", line 35, in inner
    response = get_response(request)
  File "D:\python\lib\site-packages\django\core\handlers\base.py", line 128, in _get_response
    response = self.process_exception_by_middleware(e, request)
  File "D:\python\lib\site-packages\django\core\handlers\base.py", line 126, in _get_response
    response = wrapped_callback(request, *callback_args, **callback_kwargs)
  File "C:\Users\Administrator\Desktop\python\HttpRunnerManager-master\HttpRunnerManager\activator.py", line 15, in process
    result = fun(request, index) if index else fun(request)
  File "C:\Users\Administrator\Desktop\python\HttpRunnerManager-master\ApiManager\views.py", line 53, in login
    if UserInfo.objects.filter(username__exact=username).filter(password__exact=password).count() == 1:
  File "D:\python\lib\site-packages\django\db\models\query.py", line 387, in count
    return self.query.get_count(using=self.db)
  File "D:\python\lib\site-packages\django\db\models\sql\query.py", line 491, in get_count
    number = obj.get_aggregation(using, ['__count'])['__count']
  File "D:\python\lib\site-packages\django\db\models\sql\query.py", line 476, in get_aggregation
    result = compiler.execute_sql(SINGLE)
  File "D:\python\lib\site-packages\django\db\models\sql\compiler.py", line 1066, in execute_sql
    cursor.execute(sql, params)
  File "D:\python\lib\site-packages\django\db\backends\utils.py", line 100, in execute
    return super().execute(sql, params)
  File "D:\python\lib\site-packages\django\db\backends\utils.py", line 68, in execute
    return self._execute_with_wrappers(sql, params, many=False, executor=self._execute)
  File "D:\python\lib\site-packages\django\db\backends\utils.py", line 77, in _execute_with_wrappers
    return executor(sql, params, many, context)
  File "D:\python\lib\site-packages\django\db\backends\utils.py", line 85, in _execute
    return self.cursor.execute(sql, params)
  File "D:\python\lib\site-packages\django\db\utils.py", line 89, in __exit__
    raise dj_exc_value.with_traceback(traceback) from exc_value
  File "D:\python\lib\site-packages\django\db\backends\utils.py", line 85, in _execute
    return self.cursor.execute(sql, params)
  File "D:\python\lib\site-packages\django\db\backends\mysql\base.py", line 71, in execute
    return self.cursor.execute(query, args)
  File "D:\python\lib\site-packages\MySQLdb\cursors.py", line 250, in execute
    self.errorhandler(self, exc, value)
  File "D:\python\lib\site-packages\MySQLdb\connections.py", line 50, in defaulterrorhandler
    raise errorvalue
  File "D:\python\lib\site-packages\MySQLdb\cursors.py", line 247, in execute
    res = self._query(query)
  File "D:\python\lib\site-packages\MySQLdb\cursors.py", line 411, in _query
    rowcount = self._do_query(q)
  File "D:\python\lib\site-packages\MySQLdb\cursors.py", line 374, in _do_query
    db.query(q)
  File "D:\python\lib\site-packages\MySQLdb\connections.py", line 277, in query
    _mysql.connection.query(self, query)
django.db.utils.ProgrammingError: (1146, "Table 'httprunner.userinfo' doesn't exist")
2018-07-23 09:01:26,335 [django.request:118] [exception:handle_uncaught_exception] [ERROR]- Internal Server Error: /api/login/
Traceback (most recent call last):
  File "D:\python\lib\site-packages\django\db\backends\utils.py", line 85, in _execute
    return self.cursor.execute(sql, params)
  File "D:\python\lib\site-packages\django\db\backends\mysql\base.py", line 71, in execute
    return self.cursor.execute(query, args)
  File "D:\python\lib\site-packages\MySQLdb\cursors.py", line 250, in execute
    self.errorhandler(self, exc, value)
  File "D:\python\lib\site-packages\MySQLdb\connections.py", line 50, in defaulterrorhandler
    raise errorvalue
  File "D:\python\lib\site-packages\MySQLdb\cursors.py", line 247, in execute
    res = self._query(query)
  File "D:\python\lib\site-packages\MySQLdb\cursors.py", line 411, in _query
    rowcount = self._do_query(q)
  File "D:\python\lib\site-packages\MySQLdb\cursors.py", line 374, in _do_query
    db.query(q)
  File "D:\python\lib\site-packages\MySQLdb\connections.py", line 277, in query
    _mysql.connection.query(self, query)
_mysql_exceptions.ProgrammingError: (1146, "Table 'httprunner.userinfo' doesn't exist")

The above exception was the direct cause of the following exception:

Traceback (most recent call last):
  File "D:\python\lib\site-packages\django\core\handlers\exception.py", line 35, in inner
    response = get_response(request)
  File "D:\python\lib\site-packages\django\core\handlers\base.py", line 128, in _get_response
    response = self.process_exception_by_middleware(e, request)
  File "D:\python\lib\site-packages\django\core\handlers\base.py", line 126, in _get_response
    response = wrapped_callback(request, *callback_args, **callback_kwargs)
  File "C:\Users\Administrator\Desktop\python\HttpRunnerManager-master\HttpRunnerManager\activator.py", line 15, in process
    result = fun(request, index) if index else fun(request)
  File "C:\Users\Administrator\Desktop\python\HttpRunnerManager-master\ApiManager\views.py", line 53, in login
    if UserInfo.objects.filter(username__exact=username).filter(password__exact=password).count() == 1:
  File "D:\python\lib\site-packages\django\db\models\query.py", line 387, in count
    return self.query.get_count(using=self.db)
  File "D:\python\lib\site-packages\django\db\models\sql\query.py", line 491, in get_count
    number = obj.get_aggregation(using, ['__count'])['__count']
  File "D:\python\lib\site-packages\django\db\models\sql\query.py", line 476, in get_aggregation
    result = compiler.execute_sql(SINGLE)
  File "D:\python\lib\site-packages\django\db\models\sql\compiler.py", line 1066, in execute_sql
    cursor.execute(sql, params)
  File "D:\python\lib\site-packages\django\db\backends\utils.py", line 100, in execute
    return super().execute(sql, params)
  File "D:\python\lib\site-packages\django\db\backends\utils.py", line 68, in execute
    return self._execute_with_wrappers(sql, params, many=False, executor=self._execute)
  File "D:\python\lib\site-packages\django\db\backends\utils.py", line 77, in _execute_with_wrappers
    return executor(sql, params, many, context)
  File "D:\python\lib\site-packages\django\db\backends\utils.py", line 85, in _execute
    return self.cursor.execute(sql, params)
  File "D:\python\lib\site-packages\django\db\utils.py", line 89, in __exit__
    raise dj_exc_value.with_traceback(traceback) from exc_value
  File "D:\python\lib\site-packages\django\db\backends\utils.py", line 85, in _execute
    return self.cursor.execute(sql, params)
  File "D:\python\lib\site-packages\django\db\backends\mysql\base.py", line 71, in execute
    return self.cursor.execute(query, args)
  File "D:\python\lib\site-packages\MySQLdb\cursors.py", line 250, in execute
    self.errorhandler(self, exc, value)
  File "D:\python\lib\site-packages\MySQLdb\connections.py", line 50, in defaulterrorhandler
    raise errorvalue
  File "D:\python\lib\site-packages\MySQLdb\cursors.py", line 247, in execute
    res = self._query(query)
  File "D:\python\lib\site-packages\MySQLdb\cursors.py", line 411, in _query
    rowcount = self._do_query(q)
  File "D:\python\lib\site-packages\MySQLdb\cursors.py", line 374, in _do_query
    db.query(q)
  File "D:\python\lib\site-packages\MySQLdb\connections.py", line 277, in query
    _mysql.connection.query(self, query)
django.db.utils.ProgrammingError: (1146, "Table 'httprunner.userinfo' doesn't exist")
2018-07-23 09:01:28,816 [django.request:93] [base:get_response] [WARNING]- Not Found: /
2018-07-23 09:01:38,576 [django.request:118] [exception:handle_uncaught_exception] [ERROR]- Internal Server Error: /api/login/
Traceback (most recent call last):
  File "D:\python\lib\site-packages\django\db\backends\utils.py", line 85, in _execute
    return self.cursor.execute(sql, params)
  File "D:\python\lib\site-packages\django\db\backends\mysql\base.py", line 71, in execute
    return self.cursor.execute(query, args)
  File "D:\python\lib\site-packages\MySQLdb\cursors.py", line 250, in execute
    self.errorhandler(self, exc, value)
  File "D:\python\lib\site-packages\MySQLdb\connections.py", line 50, in defaulterrorhandler
    raise errorvalue
  File "D:\python\lib\site-packages\MySQLdb\cursors.py", line 247, in execute
    res = self._query(query)
  File "D:\python\lib\site-packages\MySQLdb\cursors.py", line 411, in _query
    rowcount = self._do_query(q)
  File "D:\python\lib\site-packages\MySQLdb\cursors.py", line 374, in _do_query
    db.query(q)
  File "D:\python\lib\site-packages\MySQLdb\connections.py", line 277, in query
    _mysql.connection.query(self, query)
_mysql_exceptions.ProgrammingError: (1146, "Table 'httprunner.userinfo' doesn't exist")

The above exception was the direct cause of the following exception:

Traceback (most recent call last):
  File "D:\python\lib\site-packages\django\core\handlers\exception.py", line 35, in inner
    response = get_response(request)
  File "D:\python\lib\site-packages\django\core\handlers\base.py", line 128, in _get_response
    response = self.process_exception_by_middleware(e, request)
  File "D:\python\lib\site-packages\django\core\handlers\base.py", line 126, in _get_response
    response = wrapped_callback(request, *callback_args, **callback_kwargs)
  File "C:\Users\Administrator\Desktop\python\HttpRunnerManager-master\HttpRunnerManager\activator.py", line 15, in process
    result = fun(request, index) if index else fun(request)
  File "C:\Users\Administrator\Desktop\python\HttpRunnerManager-master\ApiManager\views.py", line 53, in login
    if UserInfo.objects.filter(username__exact=username).filter(password__exact=password).count() == 1:
  File "D:\python\lib\site-packages\django\db\models\query.py", line 387, in count
    return self.query.get_count(using=self.db)
  File "D:\python\lib\site-packages\django\db\models\sql\query.py", line 491, in get_count
    number = obj.get_aggregation(using, ['__count'])['__count']
  File "D:\python\lib\site-packages\django\db\models\sql\query.py", line 476, in get_aggregation
    result = compiler.execute_sql(SINGLE)
  File "D:\python\lib\site-packages\django\db\models\sql\compiler.py", line 1066, in execute_sql
    cursor.execute(sql, params)
  File "D:\python\lib\site-packages\django\db\backends\utils.py", line 100, in execute
    return super().execute(sql, params)
  File "D:\python\lib\site-packages\django\db\backends\utils.py", line 68, in execute
    return self._execute_with_wrappers(sql, params, many=False, executor=self._execute)
  File "D:\python\lib\site-packages\django\db\backends\utils.py", line 77, in _execute_with_wrappers
    return executor(sql, params, many, context)
  File "D:\python\lib\site-packages\django\db\backends\utils.py", line 85, in _execute
    return self.cursor.execute(sql, params)
  File "D:\python\lib\site-packages\django\db\utils.py", line 89, in __exit__
    raise dj_exc_value.with_traceback(traceback) from exc_value
  File "D:\python\lib\site-packages\django\db\backends\utils.py", line 85, in _execute
    return self.cursor.execute(sql, params)
  File "D:\python\lib\site-packages\django\db\backends\mysql\base.py", line 71, in execute
    return self.cursor.execute(query, args)
  File "D:\python\lib\site-packages\MySQLdb\cursors.py", line 250, in execute
    self.errorhandler(self, exc, value)
  File "D:\python\lib\site-packages\MySQLdb\connections.py", line 50, in defaulterrorhandler
    raise errorvalue
  File "D:\python\lib\site-packages\MySQLdb\cursors.py", line 247, in execute
    res = self._query(query)
  File "D:\python\lib\site-packages\MySQLdb\cursors.py", line 411, in _query
    rowcount = self._do_query(q)
  File "D:\python\lib\site-packages\MySQLdb\cursors.py", line 374, in _do_query
    db.query(q)
  File "D:\python\lib\site-packages\MySQLdb\connections.py", line 277, in query
    _mysql.connection.query(self, query)
django.db.utils.ProgrammingError: (1146, "Table 'httprunner.userinfo' doesn't exist")
2018-07-23 09:03:09,729 [django.request:118] [exception:handle_uncaught_exception] [ERROR]- Internal Server Error: /api/login/
Traceback (most recent call last):
  File "D:\python\lib\site-packages\django\db\backends\utils.py", line 85, in _execute
    return self.cursor.execute(sql, params)
  File "D:\python\lib\site-packages\django\db\backends\mysql\base.py", line 71, in execute
    return self.cursor.execute(query, args)
  File "D:\python\lib\site-packages\MySQLdb\cursors.py", line 250, in execute
    self.errorhandler(self, exc, value)
  File "D:\python\lib\site-packages\MySQLdb\connections.py", line 50, in defaulterrorhandler
    raise errorvalue
  File "D:\python\lib\site-packages\MySQLdb\cursors.py", line 247, in execute
    res = self._query(query)
  File "D:\python\lib\site-packages\MySQLdb\cursors.py", line 411, in _query
    rowcount = self._do_query(q)
  File "D:\python\lib\site-packages\MySQLdb\cursors.py", line 374, in _do_query
    db.query(q)
  File "D:\python\lib\site-packages\MySQLdb\connections.py", line 277, in query
    _mysql.connection.query(self, query)
_mysql_exceptions.ProgrammingError: (1146, "Table 'httprunner.userinfo' doesn't exist")

The above exception was the direct cause of the following exception:

Traceback (most recent call last):
  File "D:\python\lib\site-packages\django\core\handlers\exception.py", line 35, in inner
    response = get_response(request)
  File "D:\python\lib\site-packages\django\core\handlers\base.py", line 128, in _get_response
    response = self.process_exception_by_middleware(e, request)
  File "D:\python\lib\site-packages\django\core\handlers\base.py", line 126, in _get_response
    response = wrapped_callback(request, *callback_args, **callback_kwargs)
  File "C:\Users\Administrator\Desktop\python\HttpRunnerManager-master\HttpRunnerManager\activator.py", line 15, in process
    result = fun(request, index) if index else fun(request)
  File "C:\Users\Administrator\Desktop\python\HttpRunnerManager-master\ApiManager\views.py", line 53, in login
    if UserInfo.objects.filter(username__exact=username).filter(password__exact=password).count() == 1:
  File "D:\python\lib\site-packages\django\db\models\query.py", line 387, in count
    return self.query.get_count(using=self.db)
  File "D:\python\lib\site-packages\django\db\models\sql\query.py", line 491, in get_count
    number = obj.get_aggregation(using, ['__count'])['__count']
  File "D:\python\lib\site-packages\django\db\models\sql\query.py", line 476, in get_aggregation
    result = compiler.execute_sql(SINGLE)
  File "D:\python\lib\site-packages\django\db\models\sql\compiler.py", line 1066, in execute_sql
    cursor.execute(sql, params)
  File "D:\python\lib\site-packages\django\db\backends\utils.py", line 100, in execute
    return super().execute(sql, params)
  File "D:\python\lib\site-packages\django\db\backends\utils.py", line 68, in execute
    return self._execute_with_wrappers(sql, params, many=False, executor=self._execute)
  File "D:\python\lib\site-packages\django\db\backends\utils.py", line 77, in _execute_with_wrappers
    return executor(sql, params, many, context)
  File "D:\python\lib\site-packages\django\db\backends\utils.py", line 85, in _execute
    return self.cursor.execute(sql, params)
  File "D:\python\lib\site-packages\django\db\utils.py", line 89, in __exit__
    raise dj_exc_value.with_traceback(traceback) from exc_value
  File "D:\python\lib\site-packages\django\db\backends\utils.py", line 85, in _execute
    return self.cursor.execute(sql, params)
  File "D:\python\lib\site-packages\django\db\backends\mysql\base.py", line 71, in execute
    return self.cursor.execute(query, args)
  File "D:\python\lib\site-packages\MySQLdb\cursors.py", line 250, in execute
    self.errorhandler(self, exc, value)
  File "D:\python\lib\site-packages\MySQLdb\connections.py", line 50, in defaulterrorhandler
    raise errorvalue
  File "D:\python\lib\site-packages\MySQLdb\cursors.py", line 247, in execute
    res = self._query(query)
  File "D:\python\lib\site-packages\MySQLdb\cursors.py", line 411, in _query
    rowcount = self._do_query(q)
  File "D:\python\lib\site-packages\MySQLdb\cursors.py", line 374, in _do_query
    db.query(q)
  File "D:\python\lib\site-packages\MySQLdb\connections.py", line 277, in query
    _mysql.connection.query(self, query)
django.db.utils.ProgrammingError: (1146, "Table 'httprunner.userinfo' doesn't exist")
2018-07-23 09:05:40,007 [django.request:118] [exception:handle_uncaught_exception] [ERROR]- Internal Server Error: /api/login/
Traceback (most recent call last):
  File "D:\python\lib\site-packages\django\db\backends\utils.py", line 85, in _execute
    return self.cursor.execute(sql, params)
  File "D:\python\lib\site-packages\django\db\backends\mysql\base.py", line 71, in execute
    return self.cursor.execute(query, args)
  File "D:\python\lib\site-packages\MySQLdb\cursors.py", line 250, in execute
    self.errorhandler(self, exc, value)
  File "D:\python\lib\site-packages\MySQLdb\connections.py", line 50, in defaulterrorhandler
    raise errorvalue
  File "D:\python\lib\site-packages\MySQLdb\cursors.py", line 247, in execute
    res = self._query(query)
  File "D:\python\lib\site-packages\MySQLdb\cursors.py", line 411, in _query
    rowcount = self._do_query(q)
  File "D:\python\lib\site-packages\MySQLdb\cursors.py", line 374, in _do_query
    db.query(q)
  File "D:\python\lib\site-packages\MySQLdb\connections.py", line 277, in query
    _mysql.connection.query(self, query)
_mysql_exceptions.ProgrammingError: (1146, "Table 'httprunner.userinfo' doesn't exist")

The above exception was the direct cause of the following exception:

Traceback (most recent call last):
  File "D:\python\lib\site-packages\django\core\handlers\exception.py", line 35, in inner
    response = get_response(request)
  File "D:\python\lib\site-packages\django\core\handlers\base.py", line 128, in _get_response
    response = self.process_exception_by_middleware(e, request)
  File "D:\python\lib\site-packages\django\core\handlers\base.py", line 126, in _get_response
    response = wrapped_callback(request, *callback_args, **callback_kwargs)
  File "C:\Users\Administrator\Desktop\python\HttpRunnerManager-master\HttpRunnerManager\activator.py", line 15, in process
    result = fun(request, index) if index else fun(request)
  File "C:\Users\Administrator\Desktop\python\HttpRunnerManager-master\ApiManager\views.py", line 53, in login
    if UserInfo.objects.filter(username__exact=username).filter(password__exact=password).count() == 1:
  File "D:\python\lib\site-packages\django\db\models\query.py", line 387, in count
    return self.query.get_count(using=self.db)
  File "D:\python\lib\site-packages\django\db\models\sql\query.py", line 491, in get_count
    number = obj.get_aggregation(using, ['__count'])['__count']
  File "D:\python\lib\site-packages\django\db\models\sql\query.py", line 476, in get_aggregation
    result = compiler.execute_sql(SINGLE)
  File "D:\python\lib\site-packages\django\db\models\sql\compiler.py", line 1066, in execute_sql
    cursor.execute(sql, params)
  File "D:\python\lib\site-packages\django\db\backends\utils.py", line 100, in execute
    return super().execute(sql, params)
  File "D:\python\lib\site-packages\django\db\backends\utils.py", line 68, in execute
    return self._execute_with_wrappers(sql, params, many=False, executor=self._execute)
  File "D:\python\lib\site-packages\django\db\backends\utils.py", line 77, in _execute_with_wrappers
    return executor(sql, params, many, context)
  File "D:\python\lib\site-packages\django\db\backends\utils.py", line 85, in _execute
    return self.cursor.execute(sql, params)
  File "D:\python\lib\site-packages\django\db\utils.py", line 89, in __exit__
    raise dj_exc_value.with_traceback(traceback) from exc_value
  File "D:\python\lib\site-packages\django\db\backends\utils.py", line 85, in _execute
    return self.cursor.execute(sql, params)
  File "D:\python\lib\site-packages\django\db\backends\mysql\base.py", line 71, in execute
    return self.cursor.execute(query, args)
  File "D:\python\lib\site-packages\MySQLdb\cursors.py", line 250, in execute
    self.errorhandler(self, exc, value)
  File "D:\python\lib\site-packages\MySQLdb\connections.py", line 50, in defaulterrorhandler
    raise errorvalue
  File "D:\python\lib\site-packages\MySQLdb\cursors.py", line 247, in execute
    res = self._query(query)
  File "D:\python\lib\site-packages\MySQLdb\cursors.py", line 411, in _query
    rowcount = self._do_query(q)
  File "D:\python\lib\site-packages\MySQLdb\cursors.py", line 374, in _do_query
    db.query(q)
  File "D:\python\lib\site-packages\MySQLdb\connections.py", line 277, in query
    _mysql.connection.query(self, query)
django.db.utils.ProgrammingError: (1146, "Table 'httprunner.userinfo' doesn't exist")
2018-07-23 09:06:58,138 [HttpRunnerManager:59] [views:login] [INFO]- admin 登录失败, 请检查用户名或者密码
2018-07-23 09:07:09,244 [HttpRunnerManager:59] [views:login] [INFO]- admin 登录失败, 请检查用户名或者密码
2018-07-23 09:07:14,873 [HttpRunnerManager:59] [views:login] [INFO]- admin 登录失败, 请检查用户名或者密码
2018-07-23 09:07:18,442 [HttpRunnerManager:59] [views:login] [INFO]- admin 登录失败, 请检查用户名或者密码
2018-07-23 09:07:24,378 [HttpRunnerManager:59] [views:login] [INFO]- admin 登录失败, 请检查用户名或者密码
2018-07-23 09:07:36,930 [HttpRunnerManager:59] [views:login] [INFO]- admin 登录失败, 请检查用户名或者密码
2018-07-23 09:07:53,423 [HttpRunnerManager:31] [operation:add_register_data] [INFO]- 新增用户：ApiManager.UserInfo.objects
2018-07-23 09:08:02,028 [HttpRunnerManager:54] [views:login] [INFO]- admin 登录成功
2018-07-23 09:10:14,890 [HttpRunnerManager:58] [operation:add_project_data] [INFO]- 项目添加成功：{'project_name': '协议支付', 'responsible_name': 'HE', 'test_user': 'HE', 'dev_user': 'HE', 'publish_app': '网银充值', 'simple_desc': '630断', 'other_desc': ''}
2018-07-23 09:12:19,916 [HttpRunnerManager:106] [operation:add_module_data] [INFO]- 模块添加成功：{'module_name': '网银充值', 'test_user': 'HE', 'simple_desc': 'HE', 'other_desc': '', 'belong_project': <ProjectInfo: ProjectInfo object (1)>}
2018-07-23 09:12:42,857 [HttpRunnerManager:150] [operation:add_case_data] [INFO]- B2C用例添加成功: {'test': {'request': {'url': 'http://ser-nginx.frbao.com/frbao-baofu-recharge-portal/baofu/rechargeNet', 'method': 'POST', 'json': {'userId': '6E977136036F16F7E055000000000001', 'orderMoney': '100.02', 'pageUrl': 'https://www-test2.frbao.com', 'bankId': '3020', 'paySource': '120'}}, 'name': 'B2C'}}
2018-07-23 09:26:45,539 [HttpRunnerManager:159] [operation:add_case_data] [INFO]- B2C用例更新成功: {'test': {'request': {'url': 'http://ser-nginx.frbao.com/frbao-baofu-recharge-portal/baofu/rechargeNet', 'method': 'POST', 'json': {'userId': '6E977136036F16F7E055000000000001', 'orderMoney': '100.02', 'pageUrl': 'https://www-test2.frbao.com', 'bankId': '3020', 'paySource': '120'}}, 'name': 'B2C', 'validate': [{'comparator': 'equals', 'check': 'status', 'expected': '-1'}], 'variables': [{}]}}
2018-07-23 09:27:15,696 [HttpRunnerManager:159] [operation:add_case_data] [INFO]- B2C用例更新成功: {'test': {'request': {'url': 'http://ser-nginx.frbao.com/frbao-baofu-recharge-portal/baofu/rechargeNet', 'method': 'POST', 'json': {'userId': '6E977136036F16F7E055000000000001', 'orderMoney': '100.02', 'pageUrl': 'https://www-test2.frbao.com', 'bankId': '3020', 'paySource': '120'}}, 'name': 'B2C', 'validate': [{'comparator': 'equals', 'check': 'status', 'expected': '0'}]}}
2018-07-23 09:28:05,750 [HttpRunnerManager:159] [operation:add_case_data] [INFO]- B2C用例更新成功: {'test': {'request': {'url': 'http://ser-nginx.frbao.com/frbao-baofu-recharge-portal/baofu/rechargeNet', 'method': 'POST', 'json': {'userId': '6E977136036F16F7E055000000000001', 'orderMoney': '100.02', 'pageUrl': 'https://www-test2.frbao.com', 'bankId': '3020', 'paySource': '120'}}, 'name': 'B2C', 'validate': [{'comparator': 'equals', 'check': 'status', 'expected': 0}]}}
2018-07-23 09:29:56,152 [HttpRunnerManager:159] [operation:add_case_data] [INFO]- B2C用例更新成功: {'test': {'request': {'url': 'http://ser-nginx.frbao.com/frbao-baofu-recharge-portal/baofu/rechargeNet', 'method': 'POST', 'json': {'userId': '6E977136036F16F7E055000000000001', 'orderMoney': '100.02', 'pageUrl': 'https://www-test2.frbao.com', 'bankId': '3020', 'paySource': '120'}}, 'name': 'B2C', 'validate': [{'comparator': 'equals', 'check': 'errorInfo', 'expected': 'SUCCESS'}]}}
2018-07-23 09:31:24,824 [HttpRunnerManager:159] [operation:add_case_data] [INFO]- B2C用例更新成功: {'test': {'request': {'url': 'http://ser-nginx.frbao.com/frbao-baofu-recharge-portal/baofu/rechargeNet', 'method': 'POST', 'json': {'userId': '6E977136036F16F7E055000000000001', 'orderMoney': '100.02', 'pageUrl': 'https://www-test2.frbao.com', 'bankId': '3020', 'paySource': '120'}}, 'name': 'B2C'}}
2018-07-23 09:34:41,918 [HttpRunnerManager:159] [operation:add_case_data] [INFO]- B2C用例更新成功: {'test': {'request': {'url': 'http://ser-nginx.frbao.com/frbao-baofu-recharge-portal/baofu/rechargeNet', 'method': 'POST', 'json': {'userId': '6E977136036F16F7E055000000000001', 'orderMoney': '100.02', 'pageUrl': 'https://www-test2.frbao.com', 'bankId': '3020', 'paySource': '120'}}, 'name': 'B2C', 'validate': [{'comparator': 'equals', 'check': 'errorInfo', 'expected': 'SUCCESS'}]}}
2018-07-23 09:35:25,933 [HttpRunnerManager:159] [operation:add_case_data] [INFO]- B2C用例更新成功: {'test': {'request': {'url': 'http://ser-nginx.frbao.com/frbao-baofu-recharge-portal/baofu/rechargeNet', 'method': 'POST', 'json': {'userId': '6E977136036F16F7E055000000000001', 'orderMoney': '100.02', 'pageUrl': 'https://www-test2.frbao.com', 'bankId': '3020', 'paySource': '120'}}, 'name': 'B2C', 'validate': [{'comparator': 'equals', 'check': '‘errorInfo’', 'expected': '‘SUCCESS’'}]}}
2018-07-23 09:40:58,730 [HttpRunnerManager:159] [operation:add_case_data] [INFO]- B2C用例更新成功: {'test': {'request': {'url': 'http://ser-nginx.frbao.com/frbao-baofu-recharge-portal/baofu/rechargeNet', 'method': 'POST', 'json': {'userId': '6E977136036F16F7E055000000000001', 'orderMoney': '100.02', 'pageUrl': 'https://www-test2.frbao.com', 'bankId': '3020', 'paySource': '120'}}, 'name': 'B2C', 'validate': [{'comparator': 'equals', 'check': 'content.errorInfo', 'expected': 'SUCCESS'}]}}
2018-07-23 09:41:41,619 [HttpRunnerManager:159] [operation:add_case_data] [INFO]- B2C用例更新成功: {'test': {'request': {'url': 'http://ser-nginx.frbao.com/frbao-baofu-recharge-portal/baofu/rechargeNet', 'method': 'POST', 'json': {'userId': '6E977136036F16F7E055000000000001', 'orderMoney': '100.02', 'pageUrl': 'https://www-test2.frbao.com', 'bankId': '3020', 'paySource': '120'}}, 'name': 'B2C', 'validate': [{'comparator': 'equals', 'check': 'content.errorInfo', 'expected': 'cccc'}]}}
2018-07-23 09:46:45,777 [HttpRunnerManager:159] [operation:add_case_data] [INFO]- B2C用例更新成功: {'test': {'request': {'url': 'http://ser-nginx.frbao.com/frbao-baofu-recharge-portal/baofu/rechargeNet', 'method': 'POST', 'json': {'userId': '6E977136036F16F7E055000000000001', 'orderMoney': '100.02', 'pageUrl': 'https://www-test2.frbao.com', 'bankId': '3020', 'paySource': '120'}}, 'name': 'B2C', 'validate': [{'comparator': 'equals', 'check': 'content.status', 'expected': 0}]}}
2018-07-23 09:50:57,187 [HttpRunnerManager:150] [operation:add_case_data] [INFO]- 代付请求用例添加成功: {'test': {'request': {'url': 'http://ser-nginx.frbao.com/frbao-baofu-recharge-portal/baofu/rechargeSubstitute', 'method': 'POST', 'json': {'userId': '6CEABC2207386F10E055000000000001', 'id': '709FEA54BDE86080E055000000000001'}}, 'name': '代付请求', 'validate': [{'comparator': 'equals', 'check': 'connect.status', 'expected': '-1'}]}}
2018-07-23 09:55:50,735 [HttpRunnerManager:159] [operation:add_case_data] [INFO]- 代付请求用例更新成功: {'test': {'request': {'url': '/frbao-baofu-recharge-portal/baofu/rechargeSubstitute', 'method': 'POST', 'json': {'userId': '6CEABC2207386F10E055000000000001', 'id': '709FEA54BDE86080E055000000000001'}}, 'name': '代付请求', 'validate': [{'comparator': 'equals', 'check': 'connect.status', 'expected': '-1'}]}}
2018-07-23 09:56:07,459 [HttpRunnerManager:159] [operation:add_case_data] [INFO]- B2C用例更新成功: {'test': {'request': {'url': '/frbao-baofu-recharge-portal/baofu/rechargeNet', 'method': 'POST', 'json': {'userId': '6E977136036F16F7E055000000000001', 'orderMoney': '100.02', 'pageUrl': 'https://www-test2.frbao.com', 'bankId': '3020', 'paySource': '120'}}, 'name': 'B2C', 'validate': [{'comparator': 'equals', 'check': 'content.status', 'expected': 0}]}}
2018-07-23 10:28:20,736 [HttpRunnerManager:59] [views:login] [INFO]- admin 登录失败, 请检查用户名或者密码
2018-07-23 10:28:24,527 [HttpRunnerManager:59] [views:login] [INFO]- admin 登录失败, 请检查用户名或者密码
2018-07-23 10:28:35,973 [HttpRunnerManager:59] [views:login] [INFO]- admin 登录失败, 请检查用户名或者密码
2018-07-23 10:28:43,455 [HttpRunnerManager:59] [views:login] [INFO]- admin 登录失败, 请检查用户名或者密码
2018-07-23 10:28:49,578 [HttpRunnerManager:59] [views:login] [INFO]- admin 登录失败, 请检查用户名或者密码
2018-07-23 10:33:00,103 [HttpRunnerManager:59] [views:login] [INFO]- admin 登录失败, 请检查用户名或者密码
2018-07-23 10:33:09,792 [HttpRunnerManager:54] [views:login] [INFO]- admin 登录成功
2018-07-23 10:59:36,999 [django.request:93] [base:get_response] [WARNING]- Not Found: /
2018-07-23 12:57:36,526 [HttpRunnerManager:54] [views:login] [INFO]- admin 登录成功
2018-07-23 13:05:50,649 [HttpRunnerManager:54] [views:login] [INFO]- admin 登录成功
2018-07-23 13:42:52,117 [HttpRunnerManager:150] [operation:add_case_data] [INFO]- 对公充值用例添加成功: {'test': {'request': {'url': 'frbao-ei-fund/hg/bf/bfPay.do', 'method': 'POST', 'json': {'channel': '0069', 'channelSerialNumber': '2018061910413982133014', 'clearWays': '1', 'eAccNo': 'EA1001168902', 'merCode': '0069', 'rechargeType': '02', 'soleId': '6CC2411BB7081446E055000000000001', 'transDate': '2018-06-14', 'transTime': '08:06:23', 'txnAmt': '999'}}, 'name': '对公充值', 'validate': [{'comparator': 'equals', 'check': 'connect.responseCode', 'expected': 25}]}}
2018-07-23 13:43:37,531 [HttpRunnerManager:159] [operation:add_case_data] [INFO]- 对公充值用例更新成功: {'test': {'request': {'url': 'frbao-ei-fund/hg/bf/bfPay.do', 'method': 'POST', 'json': {'channel': '0069', 'channelSerialNumber': '2018061910413982133014', 'clearWays': '1', 'eAccNo': 'EA1001168902', 'merCode': '0069', 'rechargeType': '02', 'soleId': '6CC2411BB7081446E055000000000001', 'transDate': '2018-06-14', 'transTime': '08:06:23', 'txnAmt': '999'}}, 'name': '对公充值', 'validate': [{'comparator': 'equals', 'check': 'connect.responseMsg', 'expected': '渠道流水号重复，不能重复提交'}]}}
2018-07-23 13:44:00,222 [HttpRunnerManager:159] [operation:add_case_data] [INFO]- 对公充值用例更新成功: {'test': {'request': {'url': 'frbao-ei-fund/hg/bf/bfPay.do', 'method': 'POST', 'json': {'channel': '0069', 'channelSerialNumber': '2018061910413982133014', 'clearWays': '1', 'eAccNo': 'EA1001168902', 'merCode': '0069', 'rechargeType': '02', 'soleId': '6CC2411BB7081446E055000000000001', 'transDate': '2018-06-14', 'transTime': '08:06:23', 'txnAmt': '999'}}, 'name': '对公充值', 'validate': [{'comparator': 'equals', 'check': 'responseMsg', 'expected': '渠道流水号重复，不能重复提交'}]}}
2018-07-23 13:44:42,654 [HttpRunnerManager:159] [operation:add_case_data] [INFO]- 对公充值用例更新成功: {'test': {'request': {'url': 'frbao-ei-fund/hg/bf/bfPay.do', 'method': 'POST', 'json': {'channel': '0069', 'channelSerialNumber': '2018061910413982133014', 'clearWays': '1', 'eAccNo': 'EA1001168902', 'merCode': '0069', 'rechargeType': '02', 'soleId': '6CC2411BB7081446E055000000000001', 'transDate': '2018-06-14', 'transTime': '08:06:23', 'txnAmt': '999'}}, 'name': '对公充值', 'validate': [{'comparator': 'equals', 'check': 'content.responseMsg', 'expected': '渠道流水号重复，不能重复提交'}]}}
2018-07-23 14:03:03,025 [django.request:93] [base:get_response] [WARNING]- Not Found: /
2018-07-23 15:35:04,758 [HttpRunnerManager:54] [views:login] [INFO]- admin 登录成功
2018-07-23 17:08:22,917 [HttpRunnerManager:54] [views:login] [INFO]- admin 登录成功
2018-07-24 08:22:35,378 [HttpRunnerManager:54] [views:login] [INFO]- admin 登录成功
2018-07-24 08:41:10,120 [HttpRunnerManager:159] [operation:add_case_data] [INFO]- B2C用例更新成功: {'test': {'request': {'url': '/frbao-baofu-recharge-portal/baofu/rechargeNet', 'method': 'POST', 'json': {'userId': '6E977136036F16F7E055000000000001', 'orderMoney': '100.02', 'pageUrl': 'https://www-test2.frbao.com', 'bankId': '3020', 'paySource': '120'}}, 'name': 'B2C', 'validate': [{'comparator': 'equals', 'check': 'content.status', 'expected': '0'}]}}
2018-07-24 08:41:38,260 [HttpRunnerManager:159] [operation:add_case_data] [INFO]- 对公充值用例更新成功: {'test': {'request': {'url': '/frbao-ei-fund/hg/bf/bfPay.do', 'method': 'POST', 'json': {'channel': '0069', 'channelSerialNumber': '2018061910413982133014', 'clearWays': '1', 'eAccNo': 'EA1001168902', 'merCode': '0069', 'rechargeType': '02', 'soleId': '6CC2411BB7081446E055000000000001', 'transDate': '2018-06-14', 'transTime': '08:06:23', 'txnAmt': '999'}}, 'name': '对公充值', 'validate': [{'comparator': 'equals', 'check': 'content.responseMsg', 'expected': '渠道流水号重复，不能重复提交'}]}}
2018-07-24 08:41:52,792 [HttpRunnerManager:159] [operation:add_case_data] [INFO]- B2C用例更新成功: {'test': {'request': {'url': '/frbao-baofu-recharge-portal/baofu/rechargeNet', 'method': 'POST', 'json': {'userId': '6E977136036F16F7E055000000000001', 'orderMoney': '100.02', 'pageUrl': 'https://www-test2.frbao.com', 'bankId': '3020', 'paySource': '120'}}, 'name': 'B2C', 'validate': [{'comparator': 'equals', 'check': 'content.status', 'expected': '1'}]}}
2018-07-24 11:01:51,355 [django.request:93] [base:get_response] [WARNING]- Not Found: /
2018-07-24 11:06:13,567 [HttpRunnerManager:150] [operation:add_case_data] [INFO]- 网银充值_该用户虚户不存在用例添加成功: {'test': {'request': {'url': '/frbao-baofu-recharge-portal/baofu/rechargeNet', 'method': 'POST', 'json': {'userId': '', 'orderMoney': '100.02', 'pageUrl': 'https://www-test2.frbao.com', 'bankId': '3020', 'paySource': '120'}}, 'name': '网银充值_该用户虚户不存在', 'validate': [{'comparator': 'equals', 'check': 'content.errorInfo', 'expected': '该用户虚户不存在'}]}}
2018-07-24 11:07:45,803 [HttpRunnerManager:159] [operation:add_case_data] [INFO]- 网银充值_该用户虚户不存在用例更新成功: {'test': {'request': {'url': '/frbao-baofu-recharge-portal/baofu/rechargeNet', 'method': 'POST', 'json': {'userId': '', 'orderMoney': '100.02', 'pageUrl': 'https://www-test2.frbao.com', 'bankId': '3020', 'paySource': '120'}}, 'name': '网银充值_该用户虚户不存在', 'validate': [{'comparator': 'equals', 'check': 'content.errorInfo', 'expected': '该用户虚户不存在!'}]}}
